Workbook
Name Slicer_Category: #N/A
Name Slicer_VC_Project: #N/A

Sheet Dashboard
B2: Project Cost Saving Dashboard: Semicon Company XYZ
AB5: Project Name | AC5: Labor | AD5: Yield | AE5: Material | AF5: Total
AB6: =DataTrans!I3 -> Aut Visual 2 | AC6: =DataTrans!J3 -> 1601.7785 | AD6: =DataTrans!K3 -> 0 | AE6: =DataTrans!L3 -> 1242071.3 | AF6: =DataTrans!N3 -> 1243673.1
AB7: =DataTrans!I4 -> New Etching Chemical Potassium Iodide | AC7: =DataTrans!J4 -> 466323.5 | AD7: =DataTrans!K4 -> 0 | AE7: =DataTrans!L4 -> 542395.07 | AF7: =DataTrans!N4 -> 1008718.6
AB8: =DataTrans!I5 -> Diamond blade Supplier X | AC8: =DataTrans!J5 -> 142724.31 | AD8: =DataTrans!K5 -> 0 | AE8: =DataTrans!L5 -> 138102.62 | AF8: =DataTrans!N5 -> 280826.93
AB9: =DataTrans!I6 -> New Etching Chemical Iodine | AC9: =DataTrans!J6 -> 203284.77 | AD9: =DataTrans!K6 -> 0 | AE9: =DataTrans!L6 -> 0 | AF9: =DataTrans!N6 -> 203284.77
AB10: =DataTrans!I7 -> New Etching Chemical Diammonium Cerium | AC10: =DataTrans!J7 -> 43275.074 | AD10: =DataTrans!K7 -> 137338.4 | AE10: =DataTrans!L7 -> 19756.958 | AF10: =DataTrans!N7 -> 200370.43
AB11: =DataTrans!I8 -> Sampling Size Reduction | AC11: =DataTrans!J8 -> 0 | AD11: =DataTrans!K8 -> 0 | AE11: =DataTrans!L8 -> 172527.2 | AF11: =DataTrans!N8 -> 172527.2
AB12: =DataTrans!I9 -> Chip Cleaning Solvent 1 | AC12: =DataTrans!J9 -> 62659.888 | AD12: =DataTrans!K9 -> 0 | AE12: =DataTrans!L9 -> 76255.19 | AF12: =DataTrans!N9 -> 138915.08
AB13: =DataTrans!I10 -> Pt Target Supplier X | AC13: =DataTrans!J10 -> 92892.078 | AD13: =DataTrans!K10 -> 0 | AE13: =DataTrans!L10 -> 38820.75 | AF13: =DataTrans!N10 -> 131712.83
AB14: =DataTrans!I11 -> TiW etching increase Frequency usage | AC14: =DataTrans!J11 -> 7607.562 | AD14: =DataTrans!K11 -> 121230.93 | AE14: =DataTrans!L11 -> 0 | AF14: =DataTrans!N11 -> 128838.49
AB15: =DataTrans!I12 -> Diamond blade Supplier D | AC15: =DataTrans!J12 -> 113037.62 | AD15: =DataTrans!K12 -> 0 | AE15: =DataTrans!L12 -> -3390.3375 | AF15: =DataTrans!N12 -> 109647.28
C19: Savings | E19: Process Line | G19: Labor | I19: Yield | K19: Material | M19: Total
C21: Calendar Cost Saving | E21: =DataTrans!AN24 -> XWP | G21: =DataTrans!AO24 -> 1193828.4 | I21: =DataTrans!AP24 -> 369977.72 | K21: =DataTrans!AQ24 -> 757646.15 | M21: =SUM(G21:N22) -> 2321452.3
E23: =DataTrans!AN25 -> XCI | G23: =DataTrans!AO25 -> 1601.7785 | I23: =DataTrans!AP25 -> 0 | K23: =DataTrans!AQ25 -> 1242071.3 | M23: =SUM(G23:N24) -> 1243673.1
E25: =DataTrans!AN26 -> XCD | G25: =DataTrans!AO26 -> 553090.65 | I25: =DataTrans!AP26 -> 0 | K25: =DataTrans!AQ26 -> 600742.02 | M25: =SUM(G25:N26) -> 1153832.7
C27: Annual Cost Saving | E27: =DataTrans!AN27 -> XWP | G27: =DataTrans!AO27 -> 3604604.7 | I27: =DataTrans!AP27 -> 1117469.8 | K27: =DataTrans!AQ27 -> 2439119.5 | M27: =SUM(G27:N28) -> 7161194
E29: =DataTrans!AN28 -> XCI | G29: =DataTrans!AO28 -> 2491.3644 | I29: =DataTrans!AP28 -> 0 | K29: =DataTrans!AQ28 -> 2316135.6 | M29: =SUM(G29:N30) -> 2318627
E31: =DataTrans!AN29 -> XCD | G31: =DataTrans!AO29 -> 1174575 | I31: =DataTrans!AP29 -> 0 | K31: =DataTrans!AQ29 -> 1243923.8 | M31: =SUM(G31:N32) -> 2418498.8

Sheet Quaterly_DB
B2: Quarterly Saving Summary
C5: Classification | E5: Calendar Savings | J5: Annual Saving
E6: Q1 | F6: Q2 | G6: Q3 | H6: Q4 | I6: Total | J6: Q1 | K6: Q2 | L6: Q3 | M6: Q4 | N6: Total
C7: Process Line | D7: XWP | E7: =DataTrans!AX14 -> 263865.25 | F7: =DataTrans!AY14 -> 233706.44 | G7: =DataTrans!AZ14 -> 563170.23 | H7: =DataTrans!BA14 -> 1260712.6 | I7: =SUM(E7:H7) -> 2321454.6 | J7: =DataTrans!BB14 -> 2004023.6 | K7: =DataTrans!BC14 -> 1858718.9 | L7: =DataTrans!BD14 -> 1784037.1 | M7: =DataTrans!BE14 -> 1514414.5 | N7: =SUM(J7:M7) -> 7161194
D8: XCI | E8: =DataTrans!AX15 -> 0 | F8: =DataTrans!AY15 -> 60867.397 | G8: =DataTrans!AZ15 -> 617504.4 | H8: =DataTrans!BA15 -> 565301.32 | I8: =SUM(E8:H8) -> 1243673.1 | J8: =DataTrans!BB15 -> 544050.23 | K8: =DataTrans!BC15 -> 591771 | L8: =DataTrans!BD15 -> 617504.4 | M8: =DataTrans!BE15 -> 565301.32 | N8: =SUM(J8:M8) -> 2318627
D9: XCD | E9: =DataTrans!AX16 -> 74985.574 | F9: =DataTrans!AY16 -> 352974.64 | G9: =DataTrans!AZ16 -> 350062.47 | H9: =DataTrans!BA16 -> 375809.98 | I9: =SUM(E9:H9) -> 1153832.7 | J9: =DataTrans!BB16 -> 740210.55 | K9: =DataTrans!BC16 -> 675165.49 | L9: =DataTrans!BD16 -> 556114.08 | M9: =DataTrans!BE16 -> 447008.68 | N9: =SUM(J9:M9) -> 2418498.8
D37: XCI
D39: XCD

Sheet Proj_Reg
B2: Project Number | C2: VC Project | D2: Category | E2: Project Name | F2: Status | G2: Start Date | H2: End Date | I2: Remarks | J2: Costing Assum / actual
B3: AME25-001 | C3: Sputtering | D3: XWP | E3: TiW Target Supplier Y | G3: 45717 | H3: =EDATE(G3,11) -> 46054
B4: AME25-002 | C4: Sputtering | D4: XWP | E4: TiW Target Supplier X | G4: 45778 | H4: =EDATE(G4,11) -> 46113
B5: AME25-003 | C5: Sputtering | D5: XWP | E5: TiW Target Supplier Z | G5: 45809 | H5: =EDATE(G5,11) -> 46143
B6: AME25-004 | C6: Sputtering | D6: XWP | E6: Au Target Supplier Y | G6: 45931 | H6: =EDATE(G6,11) -> 46266
B7: AME25-005 | C7: Sputtering | D7: XWP | E7: Au Target Supplier X | G7: 45962 | H7: =EDATE(G7,11) -> 46296
B8: AME25-006 | C8: Sputtering | D8: XWP | E8: Au Target Supplier Z | G8: 45962 | H8: =EDATE(G8,11) -> 46296
B9: AME25-007 | C9: Sputtering | D9: XWP | E9: Pt Target Supplier Y | G9: 46054 | H9: =EDATE(G9,11) -> 46388
B10: AME25-008 | C10: Sputtering | D10: XWP | E10: Pt Target Supplier X | G10: 45931 | H10: =EDATE(G10,11) -> 46266
B11: AME25-009 | C11: Sputtering | D11: XWP | E11: Pt Target Supplier Z | G11: 46054 | H11: =EDATE(G11,11) -> 46388 | I11: Update 1+11
B12: AME25-010 | C12: Sputtering | D12: XWP | E12: NiCr Target Supplier Y | G12: 46082 | H12: =EDATE(G12,11) -> 46419
B13: AME25-011 | C13: Sputtering | D13: XWP | E13: NiCr Target Supplier X | G13: 46082 | H13: =EDATE(G13,11) -> 46419 | I13: Update 1+11
B14: AME25-012 | C14: Sputtering | D14: XWP | E14: NiCr Target Supplier Z | G14: 46143 | H14: =EDATE(G14,11) -> 46478
B15: AME25-013 | C15: Sputtering | D15: XWP | E15: Ti Target Supplier Y | G15: 46174 | H15: =EDATE(G15,11) -> 46508
B16: AME25-014 | C16: Sputtering | D16: XWP | E16: Ti Target Supplier X | G16: 46054 | H16: =EDATE(G16,11) -> 46388
B17: AME25-015 | C17: Sputtering | D17: XWP | E17: Ti Target Supplier Z | G17: 46113 | H17: =EDATE(G17,11) -> 46447
B18: AME25-016 | C18: Sputtering | D18: XWP | E18: Au Target Thickness 0.1um | G18: 46113 | H18: =EDATE(G18,11) -> 46447
B19: AME25-017 | C19: Sputtering | D19: XWP | E19: Au Target Thickness 0.5um | G19: 46054 | H19: =EDATE(G19,11) -> 46388
B20: AME25-018 | C20: Sputtering | D20: XWP | E20: Au Target Thickness 1.0um | G20: #N/A | H20: =EDATE(G20,11) -> #N/A
B21: AME25-019 | C21: Sputtering | D21: XWP | E21: Au Target Thickness 1.5um | G21: #N/A | H21: =EDATE(G21,11) -> #N/A
B22: AME25-020 | C22: Sputtering | D22: XWP | E22: Au Target Thickness 2.0um | G22: #N/A | H22: =EDATE(G22,11) -> #N/A
B23: AME25-021 | C23: Sputtering | D23: XWP | E23: Au Target Thickness 3.5um | G23: 46113 | H23: =EDATE(G23,11) -> 46447
B24: AME25-030 | C24: Wafer Saw Dicing | D24: XCD | E24: Diamond blade Supplier A | G24: 46113 | H24: =EDATE(G24,11) -> 46447
B25: AME25-031 | C25: Wafer Saw Dicing | D25: XCD | E25: Diamond blade Supplier B | G25: 46113 | H25: =EDATE(G25,11) -> 46447
B26: AME25-032 | C26: Wafer Saw Dicing | D26: XCD | E26: Diamond blade Supplier C | G26: #N/A | H26: =EDATE(G26,11) -> #N/A
B27: AME25-033 | C27: Wafer Saw Dicing | D27: XCD | E27: Diamond blade Supplier D | G27: 46054 | H27: =EDATE(G27,11) -> 46388
B28: AME25-034 | C28: Wafer Saw Dicing | D28: XCD | E28: Diamond blade Supplier E | G28: 46113 | H28: =EDATE(G28,11) -> 46447
B29: AME25-035 | C29: Wafer Saw Dicing | D29: XCD | E29: Diamond blade Supplier X | G29: 46054 | H29: =EDATE(G29,11) -> 46388
B30: AME25-036 | C30: Wafer Saw Dicing | D30: XCD | E30: Diamond blade Supplier Y | G30: #N/A | H30: =EDATE(G30,11) -> #N/A
B31: AME25-037 | C31: Wafer Saw Dicing | D31: XCD | E31: Diamond blade Supplier Z | G31: 46143 | H31: =EDATE(G31,11) -> 46478
B32: AME25-038 | C32: Wafer Saw Dicing | D32: XCD | E32: Thermal Release Tape 1 | G32: 46113 | H32: =EDATE(G32,11) -> 46447
B33: AME25-039 | C33: Wafer Saw Dicing | D33: XCD | E33: Thermal Release Tape 2 | G33: 46113 | H33: =EDATE(G33,11) -> 46447
B34: AME25-040 | C34: Wafer Saw Dicing | D34: XCD | E34: Thermal Release Tape 3 | G34: 46113 | H34: =EDATE(G34,11) -> 46447
B35: AME25-041 | C35: Wafer Saw Dicing | D35: XCD | E35: Tape Dicing 1 | G35: 46143 | H35: =EDATE(G35,11) -> 46478
B36: AME25-042 | C36: Wafer Saw Dicing | D36: XCD | E36: Tape Dicing 2 | G36: #N/A | H36: =EDATE(G36,11) -> #N/A
B37: AME25-043 | C37: Wafer Saw Dicing | D37: XCD | E37: Tape Dicing 3 | G37: 46266 | H37: =EDATE(G37,11) -> 46600
B38: AME25-044 | C38: Wafer Saw Dicing | D38: XCD | E38: Oven time time Reduction 25% | G38: 46296 | H38: =EDATE(G38,11) -> 46631
B39: AME25-045 | C39: Wafer Saw Dicing | D39: XCD | E39: Oven time time Reduction 50% | G39: 46327 | H39: =EDATE(G39,11) -> 46661
B40: AME25-046 | C40: Wafer Saw Dicing | D40: XCD | E40: Oven time time Reduction 75% | G40: 46327 | H40: =EDATE(G40,11) -> 46661
B41: AME25-047 | C41: Wafer Saw Dicing | D41: XCD | E41: Chip Cleaning Solvent 1 | G41: 46082 | H41: =EDATE(G41,11) -> 46419
...

Sheet Data_Model
Q1: 46023 | R1: 46054 | S1: 46082 | T1: 46113 | U1: 46143 | V1: 46174 | W1: 46204 | X1: 46235 | Y1: 46266 | Z1: 46296 | AA1: 46327 | AB1: 46357
A2: CODE 1 | B2: CODE 2 | C2: Project Number | D2: Part Number | E2: VAM-REC | F2: Start Date | G2: End Date | H2: VC Project | I2: Category | J2: Project Name | K2: Labor Saving | L2: Yield Saving | M2: Material Saving | N2: OH Saving | O2: Total Saving | P2: Status | Q2: Jan | R2: Feb | S2: Mar | T2: Apr | U2: May | V2: Jun | W2: Jul | X2: Aug | Y2: Sep | Z2: Oct | AA2: Nov | AB2: Dec | AC2: Calendar Volume2 | AD2: Jan_CSV | AE2: Feb_CSV | AF2: Mar_CSV | AG2: Apr_CSV | AH2: May_CSV | AI2: Jun_CSV | AJ2: Jul_CSV | AK2: Aug_CSV | AL2: Sep_CSV | AM2: Oct_CSV | AN2: Nov_CSV | AO2: Dec_CSV | AP2: Cal_Q1 Saving | AQ2: Cal_Q2 Saving | AR2: Cal_Q3 Saving | AS2: Cal_Q4 Saving | AT2: Column4 | AU2: Labor_CSV | AV2: Yield_CSV | AW2: Material_CSV | AX2: OH_CSV | AY2: Total__CSV | AZ2: Jan_AVF | BA2: Feb_AVF | BB2: Mar_AVF | BC2: Apr_AVF | BD2: May_AVF | BE2: Jun_AVF | BF2: Jul_AVF | BG2: Aug_AVF | BH2: Sep_AVF | BI2: Oct_AVF | BJ2: Nov_AVF | BK2: Dec_AVF | BL2: Annual Volume | BM2: Jan_ASV | BN2: Feb_ASV | BO2: Mar_ASV | BP2: Apr_ASV | BQ2: May_ASV | BR2: Jun_ASV | BS2: Jul_ASV | BT2: Aug_ASV | BU2: Sep_ASV | BV2: Oct_ASV | BW2: Nov_ASV | BX2: Dec_ASV | BY2: Ann_Q1 Saving | BZ2: Ann_Q2 Saving | CA2: Ann_Q3 Saving | CB2: Ann_Q4 Saving | CC2: Labor_ASV | CD2: Yield_ASV | CE2: Material_ASV | CF2: OH_ASV | CG2: Total_ASV
A3: =Table1[[#This Row],[Project Name]]&Table1[[#This Row],[Part Number]] -> TiW Target Supplier YR54 | B3: =IFERROR(Table1[[#This Row],[Project Number]]&Table1[[#This Row],[Part Number]],"") -> AME25-001R54 | C3: AME25-001 | D3: R54 | E3: REC | F3: =INDEX(Proj_Reg!G:G,MATCH($C3,Proj_Reg!$B:$B,0),1) -> 45717 | G3: =INDEX(Proj_Reg!H:H,MATCH($C3,Proj_Reg!$B:$B,0),1) -> 46054 | H3: =IF(INDEX(Proj_Reg!C:C,MATCH($C3,Proj_Reg!$B:$B,0),1)=0,"",INDEX(Proj_Reg!C:C,MATCH($C3,Proj_Reg!$B:$B,0),1)) -> Sputtering | I3: =IF(INDEX(Proj_Reg!D:D,MATCH($C3,Proj_Reg!$B:$B,0),1)=0,"",INDEX(Proj_Reg!D:D,MATCH($C3,Proj_Reg!$B:$B,0),1)) -> XWP | J3: =INDEX(Proj_Reg!E:E,MATCH($C3,Proj_Reg!$B:$B,0),1) -> TiW Target Supplier Y | K3: 0.01164 | L3: 0 | M3: 0.0074019243 | N3: 0 | O3: =SUM(Table1[[#This Row],[Labor Saving]:[OH Saving]]) -> 0.019041924 | Q3: =IFERROR(IF($F3=Q$1,0.3,IF(AND(Q$1>$F3,Q$1<=$G3),100%,0))*AZ3,"") -> 1421660 | R3: =IFERROR(IF($F3=R$1,0.3,IF(AND(R$1>$F3,R$1<=$G3),100%,0))*BA3,"") -> 1201487 | S3: =IFERROR(IF($F3=S$1,0.3,IF(AND(S$1>$F3,S$1<=$G3),100%,0))*BB3,"") -> 0 | T3: =IFERROR(IF($F3=T$1,0.3,IF(AND(T$1>$F3,T$1<=$G3),100%,0))*BC3,"") -> 0 | U3: =IFERROR(IF($F3=U$1,0.3,IF(AND(U$1>$F3,U$1<=$G3),100%,0))*BD3,"") -> 0 | V3: =IFERROR(IF($F3=V$1,0.3,IF(AND(V$1>$F3,V$1<=$G3),100%,0))*BE3,"") -> 0 | W3: =IFERROR(IF($F3=W$1,0.3,IF(AND(W$1>$F3,W$1<=$G3),100%,0))*BF3,"") -> 0 | X3: =IFERROR(IF($F3=X$1,0.3,IF(AND(X$1>$F3,X$1<=$G3),100%,0))*BG3,"") -> 0 | Y3: =IFERROR(IF($F3=Y$1,0.7,IF(AND(Y$1>$F3,Y$1<=$G3),100%,0))*BH3,"") -> 0 | Z3: =IFERROR(IF($F3=Z$1,0.3,IF(AND(Z$1>$F3,Z$1<=$G3),100%,0))*BI3,"") -> 0 | AA3: =IFERROR(IF($F3=AA$1,0.3,IF(AND(AA$1>$F3,AA$1<=$G3),100%,0))*BJ3,"") -> 0 | AB3: =IFERROR(IF($F3=AB$1,0.3,IF(AND(AB$1>$F3,AB$1<=$G3),100%,0))*BK3,"") -> 0 | AC3: =SUM(Table1[[#This Row],[Jan]:[Dec]]) -> 2623147 | AD3: =IFERROR($O3*Q3,"") -> 27071.142 | AE3: =IFERROR($O3*R3,"") -> 22878.624 | AF3: =IFERROR($O3*S3,"") -> 0 | AG3: =IFERROR($O3*T3,"") -> 0 | AH3: =IFERROR($O3*U3,"") -> 0 | AI3: =IFERROR($O3*V3,"") -> 0 | AJ3: =IFERROR($O3*W3,"") -> 0 | AK3: =IFERROR($O3*X3,"") -> 0 | ... AO3: =IFERROR($O3*AB3,"") -> 0 | AP3: =SUM(AD3:AF3) -> 49949.766 | AQ3: =SUM(AG3:AI3) -> 0 | AR3: =SUM(AJ3:AL3) -> 0 | AS3: =SUM(AM3:AO3) -> 0 | AT3: =SUM(AD3:AO3)=SUM(AP3:AS3) -> TRUE | AU3: =IFERROR(K3*SUM($Q3:$AB3),"") -> 30533.431 | AV3: =IFERROR(L3*SUM($Q3:$AB3),"") -> 0 | AW3: =IFERROR(M3*SUM($Q3:$AB3),"") -> 19416.335 | AX3: =IFERROR(N3*SUM($Q3:$AB3),"") -> 0 | AY3: =SUM(AU3:AX3) -> 49949.766 | AZ3: =IFERROR(IF($E3="REC",INDEX(A_Type_Volume!$B:$B,MATCH($D3,A_Type_Volume!$A:$A,0),1),IF($E3="VAM",INDEX(C_Type_Volume!$B:$B,MATCH($D3,C_Type_Volume!$A:$A,0),1),"X")),"") -> 1421660 | BA3: =IFERROR(IF($E3="REC",INDEX(A_Type_Volume!$C:$C,MATCH($D3,A_Type_Volume!$A:$A,0),1),IF($E3="VAM",INDEX(C_Type_Volume!$C:$C,MATCH($D3,C_Type_Volume!$A:$A,0),1),"X")),"") -> 1201487 | BB3: =IFERROR(IF($E3="REC",INDEX(A_Type_Volume!$D:$D,MATCH($D3,A_Type_Volume!$A:$A,0),1),IF($E3="VAM",INDEX(C_Type_Volume!$D:$D,MATCH($D3,C_Type_Volume!$A:$A,0),1),"X")),"") -> 1261172 | BC3: =IFERROR(IF($E3="REC",INDEX(A_Type_Volume!$E:$E,MATCH($D3,A_Type_Volume!$A:$A,0),1),IF($E3="VAM",INDEX(C_Type_Volume!$E:$E,MATCH($D3,C_Type_Volume!$A:$A,0),1),"X")),"") -> 1290266 | BD3: =IFERROR(IF($E3="REC",INDEX(A_Type_Volume!$F:$F,MATCH($D3,A_Type_Volume!$A:$A,0),1),IF($E3="VAM",INDEX(C_Type_Volume!$F:$F,MATCH($D3,C_Type_Volume!$A:$A,0),1),"X")),"") -> 1531466 | BE3: =IFERROR(IF($E3="REC",INDEX(A_Type_Volume!$G:$G,MATCH($D3,A_Type_Volume!$A:$A,0),1),IF($E3="VAM",INDEX(C_Type_Volume!$G:$G,MATCH($D3,C_Type_Volume!$A:$A,0),1),"X")),"") -> 1259806 | BF3: =IFERROR(IF($E3="REC",INDEX(A_Type_Volume!$H:$H,MATCH($D3,A_Type_Volume!$A:$A,0),1),IF($E3="VAM",INDEX(C_Type_Volume!$H:$H,MATCH($D3,C_Type_Volume!$A:$A,0),1),"X")),"") -> 1418923 | BG3: =IFERROR(IF($E3="REC",INDEX(A_Type_Volume!$I:$I,MATCH($D3,A_Type_Volume!$A:$A,0),1),IF($E3="VAM",INDEX(C_Type_Volume!$I:$I,MATCH($D3,C_Type_Volume!$A:$A,0),1),"X")),"") -> 968297 | BH3: =IFERROR(IF($E3="REC",INDEX(A_Type_Volume!$J:$J,MATCH($D3,A_Type_Volume!$A:$A,0),1),IF($E3="VAM",INDEX(C_Type_Volume!$J:$J,MATCH($D3,C_Type_Volume!$A:$A,0),1),"X")),"") -> 1021859 | BI3: =IFERROR(IF($E3="REC",INDEX(A_Type_Volume!$K:$K,MATCH($D3,A_Type_Volume!$A:$A,0),1),IF($E3="VAM",INDEX(C_Type_Volume!$K:$K,MATCH($D3,C_Type_Volume!$A:$A,0),1),"X")),"") -> 960468 | BJ3: =IFERROR(IF($E3="REC",INDEX(A_Type_Volume!$L:$L,MATCH($D3,A_Type_Volume!$A:$A,0),1),IF($E3="VAM",INDEX(C_Type_Volume!$L:$L,MATCH($D3,C_Type_Volume!$A:$A,0),1),"X")),"") -> 876790 | BK3: =IFERROR(IF($E3="REC",INDEX(A_Type_Volume!M:M,MATCH($D3,A_Type_Volume!$A:$A,0),1),IF($E3="VAM",INDEX(C_Type_Volume!M:M,MATCH($D3,C_Type_Volume!$A:$A,0),1),"X")),"") -> 704324 | BL3: =SUM(Table1[[#This Row],[Jan_AVF]:[Dec_AVF]]) -> 13916518 | BM3: =AZ3*$O3 -> 27071.142 | BN3: =BA3*$O3 -> 22878.624 | BO3: =BB3*$O3 -> 24015.142 | BP3: =BC3*$O3 -> 24569.147 | BQ3: =BD3*$O3 -> 29162.06 | BR3: =BE3*$O3 -> 23989.13 | BS3: =BF3*$O3 -> 27019.024 | BT3: =BG3*$O3 -> 18438.238 | ... BX3: =BK3*$O3 -> 13411.684 | BY3: =IFERROR(SUM(BM3:BO3),"") -> 73964.908 | BZ3: =IFERROR(SUM(BP3:BR3),"") -> 77720.337 | CA3: =IFERROR(SUM(BS3:BU3),"") -> 64915.424 | CB3: =IFERROR(SUM(BV3:BX3),"") -> 48396.612 | CC3: =IFERROR(Table1[[#This Row],[Labor Saving]]*Table1[[#This Row],[Annual Volume]],"") -> 161988.27 | CD3: =IFERROR(Table1[[#This Row],[Annual Volume]]*Table1[[#This Row],[Yield Saving]],"") -> 0 | CE3: =IFERROR(Table1[[#This Row],[Annual Volume]]*Table1[[#This Row],[Material Saving]],"") -> 103009.01 | CF3: =IFERROR(Table1[[#This Row],[OH Saving]]*Table1[[#This Row],[Annual Volume]],"") -> 0 | CG3: =SUM(Table1[[#This Row],[Labor_ASV]:[OH_ASV]]) -> 264997.28
A4: =Table1[[#This Row],[Project Name]]&Table1[[#This Row],[Part Number]] -> TiW Target Supplier XR52 | B4: =IFERROR(Table1[[#This Row],[Project Number]]&Table1[[#This Row],[Part Number]],"") -> AME25-002R52 | C4: AME25-002 | D4: R52 | E4: REC | F4: =INDEX(Proj_Reg!G:G,MATCH($C4,Proj_Reg!$B:$B,0),1) -> 45778 | G4: =INDEX(Proj_Reg!H:H,MATCH($C4,Proj_Reg!$B:$B,0),1) -> 46113 | H4: =IF(INDEX(Proj_Reg!C:C,MATCH($C4,Proj_Reg!$B:$B,0),1)=0,"",INDEX(Proj_Reg!C:C,MATCH($C4,Proj_Reg!$B:$B,0),1)) -> Sputtering | I4: =IF(INDEX(Proj_Reg!D:D,MATCH($C4,Proj_Reg!$B:$B,0),1)=0,"",INDEX(Proj_Reg!D:D,MATCH($C4,Proj_Reg!$B:$B,0),1)) -> XWP | J4: =INDEX(Proj_Reg!E:E,MATCH($C4,Proj_Reg!$B:$B,0),1) -> TiW Target Supplier X | K4: 0.012390558 | L4: 0 | M4: 0.013319222 | N4: 0 | O4: =SUM(Table1[[#This Row],[Labor Saving]:[OH Saving]]) -> 0.02570978 | Q4: =IFERROR(IF($F4=Q$1,0.3,IF(AND(Q$1>$F4,Q$1<=$G4),100%,0))*AZ4,"") -> 632256 | R4: =IFERROR(IF($F4=R$1,0.3,IF(AND(R$1>$F4,R$1<=$G4),100%,0))*BA4,"") -> 734887 | S4: =IFERROR(IF($F4=S$1,0.3,IF(AND(S$1>$F4,S$1<=$G4),100%,0))*BB4,"") -> 743478 | T4: =IFERROR(IF($F4=T$1,0.3,IF(AND(T$1>$F4,T$1<=$G4),100%,0))*BC4,"") -> 625525 | U4: =IFERROR(IF($F4=U$1,0.3,IF(AND(U$1>$F4,U$1<=$G4),100%,0))*BD4,"") -> 0 | V4: =IFERROR(IF($F4=V$1,0.3,IF(AND(V$1>$F4,V$1<=$G4),100%,0))*BE4,"") -> 0 | W4: =IFERROR(IF($F4=W$1,0.3,IF(AND(W$1>$F4,W$1<=$G4),100%,0))*BF4,"") -> 0 | X4: =IFERROR(IF($F4=X$1,0.3,IF(AND(X$1>$F4,X$1<=$G4),100%,0))*BG4,"") -> 0 | Y4: =IFERROR(IF($F4=Y$1,0.7,IF(AND(Y$1>$F4,Y$1<=$G4),100%,0))*BH4,"") -> 0 | Z4: =IFERROR(IF($F4=Z$1,0.3,IF(AND(Z$1>$F4,Z$1<=$G4),100%,0))*BI4,"") -> 0 | AA4: =IFERROR(IF($F4=AA$1,0.3,IF(AND(AA$1>$F4,AA$1<=$G4),100%,0))*BJ4,"") -> 0 | AB4: =IFERROR(IF($F4=AB$1,0.3,IF(AND(AB$1>$F4,AB$1<=$G4),100%,0))*BK4,"") -> 0 | AC4: =SUM(Table1[[#This Row],[Jan]:[Dec]]) -> 2736146 | AD4: =IFERROR($O4*Q4,"") -> 16255.162 | AE4: =IFERROR($O4*R4,"") -> 18893.783 | AF4: =IFERROR($O4*S4,"") -> 19114.656 | AG4: =IFERROR($O4*T4,"") -> 16082.11 | AH4: =IFERROR($O4*U4,"") -> 0 | AI4: =IFERROR($O4*V4,"") -> 0 | AJ4: =IFERROR($O4*W4,"") -> 0 | AK4: =IFERROR($O4*X4,"") -> 0 | ... AO4: =IFERROR($O4*AB4,"") -> 0 | AP4: =SUM(AD4:AF4) -> 54263.601 | AQ4: =SUM(AG4:AI4) -> 16082.11 | AR4: =SUM(AJ4:AL4) -> 0 | AS4: =SUM(AM4:AO4) -> 0 | AT4: =SUM(AD4:AO4)=SUM(AP4:AS4) -> TRUE | AU4: =IFERROR(K4*SUM($Q4:$AB4),"") -> 33902.376 | AV4: =IFERROR(L4*SUM($Q4:$AB4),"") -> 0 | AW4: =IFERROR(M4*SUM($Q4:$AB4),"") -> 36443.335 | AX4: =IFERROR(N4*SUM($Q4:$AB4),"") -> 0 | AY4: =SUM(AU4:AX4) -> 70345.711 | AZ4: =IFERROR(IF($E4="REC",INDEX(A_Type_Volume!$B:$B,MATCH($D4,A_Type_Volume!$A:$A,0),1),IF($E4="VAM",INDEX(C_Type_Volume!$B:$B,MATCH($D4,C_Type_Volume!$A:$A,0),1),"X")),"") -> 632256 | BA4: =IFERROR(IF($E4="REC",INDEX(A_Type_Volume!$C:$C,MATCH($D4,A_Type_Volume!$A:$A,0),1),IF($E4="VAM",INDEX(C_Type_Volume!$C:$C,MATCH($D4,C_Type_Volume!$A:$A,0),1),"X")),"") -> 734887 | BB4: =IFERROR(IF($E4="REC",INDEX(A_Type_Volume!$D:$D,MATCH($D4,A_Type_Volume!$A:$A,0),1),IF($E4="VAM",INDEX(C_Type_Volume!$D:$D,MATCH($D4,C_Type_Volume!$A:$A,0),1),"X")),"") -> 743478 | BC4: =IFERROR(IF($E4="REC",INDEX(A_Type_Volume!$E:$E,MATCH($D4,A_Type_Volume!$A:$A,0),1),IF($E4="VAM",INDEX(C_Type_Volume!$E:$E,MATCH($D4,C_Type_Volume!$A:$A,0),1),"X")),"") -> 625525 | BD4: =IFERROR(IF($E4="REC",INDEX(A_Type_Volume!$F:$F,MATCH($D4,A_Type_Volume!$A:$A,0),1),IF($E4="VAM",INDEX(C_Type_Volume!$F:$F,MATCH($D4,C_Type_Volume!$A:$A,0),1),"X")),"") -> 713514 | BE4: =IFERROR(IF($E4="REC",INDEX(A_Type_Volume!$G:$G,MATCH($D4,A_Type_Volume!$A:$A,0),1),IF($E4="VAM",INDEX(C_Type_Volume!$G:$G,MATCH($D4,C_Type_Volume!$A:$A,0),1),"X")),"") -> 727708 | BF4: =IFERROR(IF($E4="REC",INDEX(A_Type_Volume!$H:$H,MATCH($D4,A_Type_Volume!$A:$A,0),1),IF($E4="VAM",INDEX(C_Type_Volume!$H:$H,MATCH($D4,C_Type_Volume!$A:$A,0),1),"X")),"") -> 691684 | BG4: =IFERROR(IF($E4="REC",INDEX(A_Type_Volume!$I:$I,MATCH($D4,A_Type_Volume!$A:$A,0),1),IF($E4="VAM",INDEX(C_Type_Volume!$I:$I,MATCH($D4,C_Type_Volume!$A:$A,0),1),"X")),"") -> 534040 | BH4: =IFERROR(IF($E4="REC",INDEX(A_Type_Volume!$J:$J,MATCH($D4,A_Type_Volume!$A:$A,0),1),IF($E4="VAM",INDEX(C_Type_Volume!$J:$J,MATCH($D4,C_Type_Volume!$A:$A,0),1),"X")),"") -> 637583 | BI4: =IFERROR(IF($E4="REC",INDEX(A_Type_Volume!$K:$K,MATCH($D4,A_Type_Volume!$A:$A,0),1),IF($E4="VAM",INDEX(C_Type_Volume!$K:$K,MATCH($D4,C_Type_Volume!$A:$A,0),1),"X")),"") -> 584430 | BJ4: =IFERROR(IF($E4="REC",INDEX(A_Type_Volume!$L:$L,MATCH($D4,A_Type_Volume!$A:$A,0),1),IF($E4="VAM",INDEX(C_Type_Volume!$L:$L,MATCH($D4,C_Type_Volume!$A:$A,0),1),"X")),"") -> 459465 | BK4: =IFERROR(IF($E4="REC",INDEX(A_Type_Volume!M:M,MATCH($D4,A_Type_Volume!$A:$A,0),1),IF($E4="VAM",INDEX(C_Type_Volume!M:M,MATCH($D4,C_Type_Volume!$A:$A,0),1),"X")),"") -> 454091 | BL4: =SUM(Table1[[#This Row],[Jan_AVF]:[Dec_AVF]]) -> 7538661 | BM4: =AZ4*$O4 -> 16255.162 | BN4: =BA4*$O4 -> 18893.783 | BO4: =BB4*$O4 -> 19114.656 | BP4: =BC4*$O4 -> 16082.11 | BQ4: =BD4*$O4 -> 18344.288 | BR4: =BE4*$O4 -> 18709.212 | BS4: =BF4*$O4 -> 17783.043 | BT4: =BG4*$O4 -> 13730.051 | ... BX4: =BK4*$O4 -> 11674.58 | BY4: =IFERROR(SUM(BM4:BO4),"") -> 54263.601 | BZ4: =IFERROR(SUM(BP4:BR4),"") -> 53135.61 | CA4: =IFERROR(SUM(BS4:BU4),"") -> 47905.213 | CB4: =IFERROR(SUM(BV4:BX4),"") -> 38512.89 | CC4: =IFERROR(Table1[[#This Row],[Labor Saving]]*Table1[[#This Row],[Annual Volume]],"") -> 93408.217 | CD4: =IFERROR(Table1[[#This Row],[Annual Volume]]*Table1[[#This Row],[Yield Saving]],"") -> 0 | CE4: =IFERROR(Table1[[#This Row],[Annual Volume]]*Table1[[#This Row],[Material Saving]],"") -> 100409.1 | CF4: =IFERROR(Table1[[#This Row],[OH Saving]]*Table1[[#This Row],[Annual Volume]],"") -> 0 | CG4: =SUM(Table1[[#This Row],[Labor_ASV]:[OH_ASV]]) -> 193817.31
A5: =Table1[[#This Row],[Project Name]]&Table1[[#This Row],[Part Number]] -> Aut Visual 2V3 | B5: =IFERROR(Table1[[#This Row],[Project Number]]&Table1[[#This Row],[Part Number]],"") -> AME25-066V3 | C5: AME25-066 | D5: V3 | E5: VAM | F5: =INDEX(Proj_Reg!G:G,MATCH($C5,Proj_Reg!$B:$B,0),1) -> 46174 | G5: =INDEX(Proj_Reg!H:H,MATCH($C5,Proj_Reg!$B:$B,0),1) -> 46508 | H5: =IF(INDEX(Proj_Reg!C:C,MATCH($C5,Proj_Reg!$B:$B,0),1)=0,"",INDEX(Proj_Reg!C:C,MATCH($C5,Proj_Reg!$B:$B,0),1)) -> Visual Inspection | I5: =IF(INDEX(Proj_Reg!D:D,MATCH($C5,Proj_Reg!$B:$B,0),1)=0,"",INDEX(Proj_Reg!D:D,MATCH($C5,Proj_Reg!$B:$B,0),1)) -> XCI | J5: =INDEX(Proj_Reg!E:E,MATCH($C5,Proj_Reg!$B:$B,0),1) -> Aut Visual 2 | K5: 0 | L5: 0 | M5: 0.125 | N5: 0 | O5: =SUM(Table1[[#This Row],[Labor Saving]:[OH Saving]]) -> 0.125 | Q5: =IFERROR(IF($F5=Q$1,0.3,IF(AND(Q$1>$F5,Q$1<=$G5),100%,0))*AZ5,"") -> 0 | R5: =IFERROR(IF($F5=R$1,0.3,IF(AND(R$1>$F5,R$1<=$G5),100%,0))*BA5,"") -> 0 | S5: =IFERROR(IF($F5=S$1,0.3,IF(AND(S$1>$F5,S$1<=$G5),100%,0))*BB5,"") -> 0 | T5: =IFERROR(IF($F5=T$1,0.3,IF(AND(T$1>$F5,T$1<=$G5),100%,0))*BC5,"") -> 0 | U5: =IFERROR(IF($F5=U$1,0.3,IF(AND(U$1>$F5,U$1<=$G5),100%,0))*BD5,"") -> 0 | V5: =IFERROR(IF($F5=V$1,0.3,IF(AND(V$1>$F5,V$1<=$G5),100%,0))*BE5,"") -> 243498 | W5: =IFERROR(IF($F5=W$1,0.3,IF(AND(W$1>$F5,W$1<=$G5),100%,0))*BF5,"") -> 845291 | X5: =IFERROR(IF($F5=X$1,0.3,IF(AND(X$1>$F5,X$1<=$G5),100%,0))*BG5,"") -> 777804 | Y5: =IFERROR(IF($F5=Y$1,0.7,IF(AND(Y$1>$F5,Y$1<=$G5),100%,0))*BH5,"") -> 845376 | Z5: =IFERROR(IF($F5=Z$1,0.3,IF(AND(Z$1>$F5,Z$1<=$G5),100%,0))*BI5,"") -> 879191 | AA5: =IFERROR(IF($F5=AA$1,0.3,IF(AND(AA$1>$F5,AA$1<=$G5),100%,0))*BJ5,"") -> 811677 | AB5: =IFERROR(IF($F5=AB$1,0.3,IF(AND(AB$1>$F5,AB$1<=$G5),100%,0))*BK5,"") -> 568675 | AC5: =SUM(Table1[[#This Row],[Jan]:[Dec]]) -> 4971512 | AD5: =IFERROR($O5*Q5,"") -> 0 | AE5: =IFERROR($O5*R5,"") -> 0 | AF5: =IFERROR($O5*S5,"") -> 0 | AG5: =IFERROR($O5*T5,"") -> 0 | AH5: =IFERROR($O5*U5,"") -> 0 | AI5: =IFERROR($O5*V5,"") -> 30437.25 | AJ5: =IFERROR($O5*W5,"") -> 105661.38 | AK5: =IFERROR($O5*X5,"") -> 97225.5 | ... AO5: =IFERROR($O5*AB5,"") -> 71084.375 | AP5: =SUM(AD5:AF5) -> 0 | AQ5: =SUM(AG5:AI5) -> 30437.25 | AR5: =SUM(AJ5:AL5) -> 308558.88 | AS5: =SUM(AM5:AO5) -> 282442.88 | AT5: =SUM(AD5:AO5)=SUM(AP5:AS5) -> TRUE | AU5: =IFERROR(K5*SUM($Q5:$AB5),"") -> 0 | AV5: =IFERROR(L5*SUM($Q5:$AB5),"") -> 0 | AW5: =IFERROR(M5*SUM($Q5:$AB5),"") -> 621439 | AX5: =IFERROR(N5*SUM($Q5:$AB5),"") -> 0 | AY5: =SUM(AU5:AX5) -> 621439 | AZ5: =IFERROR(IF($E5="REC",INDEX(A_Type_Volume!$B:$B,MATCH($D5,A_Type_Volume!$A:$A,0),1),IF($E5="VAM",INDEX(C_Type_Volume!$B:$B,MATCH($D5,C_Type_Volume!$A:$A,0),1),"X")),"") -> 683202 | BA5: =IFERROR(IF($E5="REC",INDEX(A_Type_Volume!$C:$C,MATCH($D5,A_Type_Volume!$A:$A,0),1),IF($E5="VAM",INDEX(C_Type_Volume!$C:$C,MATCH($D5,C_Type_Volume!$A:$A,0),1),"X")),"") -> 667394 | BB5: =IFERROR(IF($E5="REC",INDEX(A_Type_Volume!$D:$D,MATCH($D5,A_Type_Volume!$A:$A,0),1),IF($E5="VAM",INDEX(C_Type_Volume!$D:$D,MATCH($D5,C_Type_Volume!$A:$A,0),1),"X")),"") -> 652384 | BC5: =IFERROR(IF($E5="REC",INDEX(A_Type_Volume!$E:$E,MATCH($D5,A_Type_Volume!$A:$A,0),1),IF($E5="VAM",INDEX(C_Type_Volume!$E:$E,MATCH($D5,C_Type_Volume!$A:$A,0),1),"X")),"") -> 743928 | BD5: =IFERROR(IF($E5="REC",INDEX(A_Type_Volume!$F:$F,MATCH($D5,A_Type_Volume!$A:$A,0),1),IF($E5="VAM",INDEX(C_Type_Volume!$F:$F,MATCH($D5,C_Type_Volume!$A:$A,0),1),"X")),"") -> 811604 | BE5: =IFERROR(IF($E5="REC",INDEX(A_Type_Volume!$G:$G,MATCH($D5,A_Type_Volume!$A:$A,0),1),IF($E5="VAM",INDEX(C_Type_Volume!$G:$G,MATCH($D5,C_Type_Volume!$A:$A,0),1),"X")),"") -> 811660 | BF5: =IFERROR(IF($E5="REC",INDEX(A_Type_Volume!$H:$H,MATCH($D5,A_Type_Volume!$A:$A,0),1),IF($E5="VAM",INDEX(C_Type_Volume!$H:$H,MATCH($D5,C_Type_Volume!$A:$A,0),1),"X")),"") -> 845291 | BG5: =IFERROR(IF($E5="REC",INDEX(A_Type_Volume!$I:$I,MATCH($D5,A_Type_Volume!$A:$A,0),1),IF($E5="VAM",INDEX(C_Type_Volume!$I:$I,MATCH($D5,C_Type_Volume!$A:$A,0),1),"X")),"") -> 777804 | BH5: =IFERROR(IF($E5="REC",INDEX(A_Type_Volume!$J:$J,MATCH($D5,A_Type_Volume!$A:$A,0),1),IF($E5="VAM",INDEX(C_Type_Volume!$J:$J,MATCH($D5,C_Type_Volume!$A:$A,0),1),"X")),"") -> 845376 | BI5: =IFERROR(IF($E5="REC",INDEX(A_Type_Volume!$K:$K,MATCH($D5,A_Type_Volume!$A:$A,0),1),IF($E5="VAM",INDEX(C_Type_Volume!$K:$K,MATCH($D5,C_Type_Volume!$A:$A,0),1),"X")),"") -> 879191 | BJ5: =IFERROR(IF($E5="REC",INDEX(A_Type_Volume!$L:$L,MATCH($D5,A_Type_Volume!$A:$A,0),1),IF($E5="VAM",INDEX(C_Type_Volume!$L:$L,MATCH($D5,C_Type_Volume!$A:$A,0),1),"X")),"") -> 811677 | BK5: =IFERROR(IF($E5="REC",INDEX(A_Type_Volume!M:M,MATCH($D5,A_Type_Volume!$A:$A,0),1),IF($E5="VAM",INDEX(C_Type_Volume!M:M,MATCH($D5,C_Type_Volume!$A:$A,0),1),"X")),"") -> 568675 | BL5: =SUM(Table1[[#This Row],[Jan_AVF]:[Dec_AVF]]) -> 9098186 | BM5: =AZ5*$O5 -> 85400.25 | BN5: =BA5*$O5 -> 83424.25 | BO5: =BB5*$O5 -> 81548 | BP5: =BC5*$O5 -> 92991 | BQ5: =BD5*$O5 -> 101450.5 | BR5: =BE5*$O5 -> 101457.5 | BS5: =BF5*$O5 -> 105661.38 | BT5: =BG5*$O5 -> 97225.5 | ... BX5: =BK5*$O5 -> 71084.375 | BY5: =IFERROR(SUM(BM5:BO5),"") -> 250372.5 | BZ5: =IFERROR(SUM(BP5:BR5),"") -> 295899 | CA5: =IFERROR(SUM(BS5:BU5),"") -> 308558.88 | CB5: =IFERROR(SUM(BV5:BX5),"") -> 282442.88 | CC5: =IFERROR(Table1[[#This Row],[Labor Saving]]*Table1[[#This Row],[Annual Volume]],"") -> 0 | CD5: =IFERROR(Table1[[#This Row],[Annual Volume]]*Table1[[#This Row],[Yield Saving]],"") -> 0 | CE5: =IFERROR(Table1[[#This Row],[Annual Volume]]*Table1[[#This Row],[Material Saving]],"") -> 1137273.2 | CF5: =IFERROR(Table1[[#This Row],[OH Saving]]*Table1[[#This Row],[Annual Volume]],"") -> 0 | CG5: =SUM(Table1[[#This Row],[Labor_ASV]:[OH_ASV]]) -> 1137273.2
A6: =Table1[[#This Row],[Project Name]]&Table1[[#This Row],[Part Number]] -> Aut Visual 2V4 | B6: =IFERROR(Table1[[#This Row],[Project Number]]&Table1[[#This Row],[Part Number]],"") -> AME25-066V4 | C6: AME25-066 | D6: V4 | E6: VAM | F6: =INDEX(Proj_Reg!G:G,MATCH($C6,Proj_Reg!$B:$B,0),1) -> 46174 | G6: =INDEX(Proj_Reg!H:H,MATCH($C6,Proj_Reg!$B:$B,0),1) -> 46508 | H6: =IF(INDEX(Proj_Reg!C:C,MATCH($C6,Proj_Reg!$B:$B,0),1)=0,"",INDEX(Proj_Reg!C:C,MATCH($C6,Proj_Reg!$B:$B,0),1)) -> Visual Inspection | I6: =IF(INDEX(Proj_Reg!D:D,MATCH($C6,Proj_Reg!$B:$B,0),1)=0,"",INDEX(Proj_Reg!D:D,MATCH($C6,Proj_Reg!$B:$B,0),1)) -> XCI | J6: =INDEX(Proj_Reg!E:E,MATCH($C6,Proj_Reg!$B:$B,0),1) -> Aut Visual 2 | K6: 0 | L6: 0 | M6: 0.125 | N6: 0 | O6: =SUM(Table1[[#This Row],[Labor Saving]:[OH Saving]]) -> 0.125 | Q6: =IFERROR(IF($F6=Q$1,0.3,IF(AND(Q$1>$F6,Q$1<=$G6),100%,0))*AZ6,"") -> 0 | R6: =IFERROR(IF($F6=R$1,0.3,IF(AND(R$1>$F6,R$1<=$G6),100%,0))*BA6,"") -> 0 | S6: =IFERROR(IF($F6=S$1,0.3,IF(AND(S$1>$F6,S$1<=$G6),100%,0))*BB6,"") -> 0 | T6: =IFERROR(IF($F6=T$1,0.3,IF(AND(T$1>$F6,T$1<=$G6),100%,0))*BC6,"") -> 0 | U6: =IFERROR(IF($F6=U$1,0.3,IF(AND(U$1>$F6,U$1<=$G6),100%,0))*BD6,"") -> 0 | V6: =IFERROR(IF($F6=V$1,0.3,IF(AND(V$1>$F6,V$1<=$G6),100%,0))*BE6,"") -> 242502 | W6: =IFERROR(IF($F6=W$1,0.3,IF(AND(W$1>$F6,W$1<=$G6),100%,0))*BF6,"") -> 842209 | X6: =IFERROR(IF($F6=X$1,0.3,IF(AND(X$1>$F6,X$1<=$G6),100%,0))*BG6,"") -> 774696 | Y6: =IFERROR(IF($F6=Y$1,0.7,IF(AND(Y$1>$F6,Y$1<=$G6),100%,0))*BH6,"") -> 842124 | Z6: =IFERROR(IF($F6=Z$1,0.3,IF(AND(Z$1>$F6,Z$1<=$G6),100%,0))*BI6,"") -> 875809 | AA6: =IFERROR(IF($F6=AA$1,0.3,IF(AND(AA$1>$F6,AA$1<=$G6),100%,0))*BJ6,"") -> 808323 | AB6: =IFERROR(IF($F6=AB$1,0.3,IF(AND(AB$1>$F6,AB$1<=$G6),100%,0))*BK6,"") -> 566675 | AC6: =SUM(Table1[[#This Row],[Jan]:[Dec]]) -> 4952338 | AD6: =IFERROR($O6*Q6,"") -> 0 | AE6: =IFERROR($O6*R6,"") -> 0 | AF6: =IFERROR($O6*S6,"") -> 0 | AG6: =IFERROR($O6*T6,"") -> 0 | AH6: =IFERROR($O6*U6,"") -> 0 | AI6: =IFERROR($O6*V6,"") -> 30312.75 | AJ6: =IFERROR($O6*W6,"") -> 105276.12 | AK6: =IFERROR($O6*X6,"") -> 96837 | ... AO6: =IFERROR($O6*AB6,"") -> 70834.375 | AP6: =SUM(AD6:AF6) -> 0 | AQ6: =SUM(AG6:AI6) -> 30312.75 | AR6: =SUM(AJ6:AL6) -> 307378.62 | AS6: =SUM(AM6:AO6) -> 281350.88 | AT6: =SUM(AD6:AO6)=SUM(AP6:AS6) -> TRUE | AU6: =IFERROR(K6*SUM($Q6:$AB6),"") -> 0 | AV6: =IFERROR(L6*SUM($Q6:$AB6),"") -> 0 | AW6: =IFERROR(M6*SUM($Q6:$AB6),"") -> 619042.25 | AX6: =IFERROR(N6*SUM($Q6:$AB6),"") -> 0 | AY6: =SUM(AU6:AX6) -> 619042.25 | AZ6: =IFERROR(IF($E6="REC",INDEX(A_Type_Volume!$B:$B,MATCH($D6,A_Type_Volume!$A:$A,0),1),IF($E6="VAM",INDEX(C_Type_Volume!$B:$B,MATCH($D6,C_Type_Volume!$A:$A,0),1),"X")),"") -> 713167 | BA6: =IFERROR(IF($E6="REC",INDEX(A_Type_Volume!$C:$C,MATCH($D6,A_Type_Volume!$A:$A,0),1),IF($E6="VAM",INDEX(C_Type_Volume!$C:$C,MATCH($D6,C_Type_Volume!$A:$A,0),1),"X")),"") -> 603260 | BB6: =IFERROR(IF($E6="REC",INDEX(A_Type_Volume!$D:$D,MATCH($D6,A_Type_Volume!$A:$A,0),1),IF($E6="VAM",INDEX(C_Type_Volume!$D:$D,MATCH($D6,C_Type_Volume!$A:$A,0),1),"X")),"") -> 650377 | BC6: =IFERROR(IF($E6="REC",INDEX(A_Type_Volume!$E:$E,MATCH($D6,A_Type_Volume!$A:$A,0),1),IF($E6="VAM",INDEX(C_Type_Volume!$E:$E,MATCH($D6,C_Type_Volume!$A:$A,0),1),"X")),"") -> 741072 | BD6: =IFERROR(IF($E6="REC",INDEX(A_Type_Volume!$F:$F,MATCH($D6,A_Type_Volume!$A:$A,0),1),IF($E6="VAM",INDEX(C_Type_Volume!$F:$F,MATCH($D6,C_Type_Volume!$A:$A,0),1),"X")),"") -> 808396 | BE6: =IFERROR(IF($E6="REC",INDEX(A_Type_Volume!$G:$G,MATCH($D6,A_Type_Volume!$A:$A,0),1),IF($E6="VAM",INDEX(C_Type_Volume!$G:$G,MATCH($D6,C_Type_Volume!$A:$A,0),1),"X")),"") -> 808340 | BF6: =IFERROR(IF($E6="REC",INDEX(A_Type_Volume!$H:$H,MATCH($D6,A_Type_Volume!$A:$A,0),1),IF($E6="VAM",INDEX(C_Type_Volume!$H:$H,MATCH($D6,C_Type_Volume!$A:$A,0),1),"X")),"") -> 842209 | BG6: =IFERROR(IF($E6="REC",INDEX(A_Type_Volume!$I:$I,MATCH($D6,A_Type_Volume!$A:$A,0),1),IF($E6="VAM",INDEX(C_Type_Volume!$I:$I,MATCH($D6,C_Type_Volume!$A:$A,0),1),"X")),"") -> 774696 | BH6: =IFERROR(IF($E6="REC",INDEX(A_Type_Volume!$J:$J,MATCH($D6,A_Type_Volume!$A:$A,0),1),IF($E6="VAM",INDEX(C_Type_Volume!$J:$J,MATCH($D6,C_Type_Volume!$A:$A,0),1),"X")),"") -> 842124 | BI6: =IFERROR(IF($E6="REC",INDEX(A_Type_Volume!$K:$K,MATCH($D6,A_Type_Volume!$A:$A,0),1),IF($E6="VAM",INDEX(C_Type_Volume!$K:$K,MATCH($D6,C_Type_Volume!$A:$A,0),1),"X")),"") -> 875809 | BJ6: =IFERROR(IF($E6="REC",INDEX(A_Type_Volume!$L:$L,MATCH($D6,A_Type_Volume!$A:$A,0),1),IF($E6="VAM",INDEX(C_Type_Volume!$L:$L,MATCH($D6,C_Type_Volume!$A:$A,0),1),"X")),"") -> 808323 | BK6: =IFERROR(IF($E6="REC",INDEX(A_Type_Volume!M:M,MATCH($D6,A_Type_Volume!$A:$A,0),1),IF($E6="VAM",INDEX(C_Type_Volume!M:M,MATCH($D6,C_Type_Volume!$A:$A,0),1),"X")),"") -> 566675 | BL6: =SUM(Table1[[#This Row],[Jan_AVF]:[Dec_AVF]]) -> 9034448 | BM6: =AZ6*$O6 -> 89145.875 | BN6: =BA6*$O6 -> 75407.5 | BO6: =BB6*$O6 -> 81297.125 | BP6: =BC6*$O6 -> 92634 | BQ6: =BD6*$O6 -> 101049.5 | BR6: =BE6*$O6 -> 101042.5 | BS6: =BF6*$O6 -> 105276.12 | BT6: =BG6*$O6 -> 96837 | ... BX6: =BK6*$O6 -> 70834.375 | BY6: =IFERROR(SUM(BM6:BO6),"") -> 245850.5 | BZ6: =IFERROR(SUM(BP6:BR6),"") -> 294726 | CA6: =IFERROR(SUM(BS6:BU6),"") -> 307378.62 | CB6: =IFERROR(SUM(BV6:BX6),"") -> 281350.88 | CC6: =IFERROR(Table1[[#This Row],[Labor Saving]]*Table1[[#This Row],[Annual Volume]],"") -> 0 | CD6: =IFERROR(Table1[[#This Row],[Annual Volume]]*Table1[[#This Row],[Yield Saving]],"") -> 0 | CE6: =IFERROR(Table1[[#This Row],[Annual Volume]]*Table1[[#This Row],[Material Saving]],"") -> 1129306 | CF6: =IFERROR(Table1[[#This Row],[OH Saving]]*Table1[[#This Row],[Annual Volume]],"") -> 0 | CG6: =SUM(Table1[[#This Row],[Labor_ASV]:[OH_ASV]]) -> 1129306
A7: =Table1[[#This Row],[Project Name]]&Table1[[#This Row],[Part Number]] -> Aut Visual 2V1 | B7: =IFERROR(Table1[[#This Row],[Project Number]]&Table1[[#This Row],[Part Number]],"") -> AME25-066V1 | C7: AME25-066 | D7: V1 | E7: VAM | F7: =INDEX(Proj_Reg!G:G,MATCH($C7,Proj_Reg!$B:$B,0),1) -> 46174 | G7: =INDEX(Proj_Reg!H:H,MATCH($C7,Proj_Reg!$B:$B,0),1) -> 46508 | H7: =IF(INDEX(Proj_Reg!C:C,MATCH($C7,Proj_Reg!$B:$B,0),1)=0,"",INDEX(Proj_Reg!C:C,MATCH($C7,Proj_Reg!$B:$B,0),1)) -> Visual Inspection | I7: =IF(INDEX(Proj_Reg!D:D,MATCH($C7,Proj_Reg!$B:$B,0),1)=0,"",INDEX(Proj_Reg!D:D,MATCH($C7,Proj_Reg!$B:$B,0),1)) -> XCI | J7: =INDEX(Proj_Reg!E:E,MATCH($C7,Proj_Reg!$B:$B,0),1) -> Aut Visual 2 | K7: 0 | L7: 0 | M7: 0.083026776 | N7: 0 | O7: =SUM(Table1[[#This Row],[Labor Saving]:[OH Saving]]) -> 0.083026776 | Q7: =IFERROR(IF($F7=Q$1,0.3,IF(AND(Q$1>$F7,Q$1<=$G7),100%,0))*AZ7,"") -> 0 | R7: =IFERROR(IF($F7=R$1,0.3,IF(AND(R$1>$F7,R$1<=$G7),100%,0))*BA7,"") -> 0 | S7: =IFERROR(IF($F7=S$1,0.3,IF(AND(S$1>$F7,S$1<=$G7),100%,0))*BB7,"") -> 0 | T7: =IFERROR(IF($F7=T$1,0.3,IF(AND(T$1>$F7,T$1<=$G7),100%,0))*BC7,"") -> 0 | U7: =IFERROR(IF($F7=U$1,0.3,IF(AND(U$1>$F7,U$1<=$G7),100%,0))*BD7,"") -> 0 | V7: =IFERROR(IF($F7=V$1,0.3,IF(AND(V$1>$F7,V$1<=$G7),100%,0))*BE7,"") -> 0 | W7: =IFERROR(IF($F7=W$1,0.3,IF(AND(W$1>$F7,W$1<=$G7),100%,0))*BF7,"") -> 0 | X7: =IFERROR(IF($F7=X$1,0.3,IF(AND(X$1>$F7,X$1<=$G7),100%,0))*BG7,"") -> 0 | Y7: =IFERROR(IF($F7=Y$1,0.7,IF(AND(Y$1>$F7,Y$1<=$G7),100%,0))*BH7,"") -> 0 | Z7: =IFERROR(IF($F7=Z$1,0.3,IF(AND(Z$1>$F7,Z$1<=$G7),100%,0))*BI7,"") -> 0 | AA7: =IFERROR(IF($F7=AA$1,0.3,IF(AND(AA$1>$F7,AA$1<=$G7),100%,0))*BJ7,"") -> 0 | AB7: =IFERROR(IF($F7=AB$1,0.3,IF(AND(AB$1>$F7,AB$1<=$G7),100%,0))*BK7,"") -> 0 | AC7: =SUM(Table1[[#This Row],[Jan]:[Dec]]) -> 0 | AD7: =IFERROR($O7*Q7,"") -> 0 | AE7: =IFERROR($O7*R7,"") -> 0 | AF7: =IFERROR($O7*S7,"") -> 0 | AG7: =IFERROR($O7*T7,"") -> 0 | AH7: =IFERROR($O7*U7,"") -> 0 | AI7: =IFERROR($O7*V7,"") -> 0 | AJ7: =IFERROR($O7*W7,"") -> 0 | AK7: =IFERROR($O7*X7,"") -> 0 | ... AO7: =IFERROR($O7*AB7,"") -> 0 | AP7: =SUM(AD7:AF7) -> 0 | AQ7: =SUM(AG7:AI7) -> 0 | AR7: =SUM(AJ7:AL7) -> 0 | AS7: =SUM(AM7:AO7) -> 0 | AT7: =SUM(AD7:AO7)=SUM(AP7:AS7) -> TRUE | AU7: =IFERROR(K7*SUM($Q7:$AB7),"") -> 0 | AV7: =IFERROR(L7*SUM($Q7:$AB7),"") -> 0 | AW7: =IFERROR(M7*SUM($Q7:$AB7),"") -> 0 | AX7: =IFERROR(N7*SUM($Q7:$AB7),"") -> 0 | AY7: =SUM(AU7:AX7) -> 0 | AZ7: =IFERROR(IF($E7="REC",INDEX(A_Type_Volume!$B:$B,MATCH($D7,A_Type_Volume!$A:$A,0),1),IF($E7="VAM",INDEX(C_Type_Volume!$B:$B,MATCH($D7,C_Type_Volume!$A:$A,0),1),"X")),"") -> 149825 | BA7: =IFERROR(IF($E7="REC",INDEX(A_Type_Volume!$C:$C,MATCH($D7,A_Type_Volume!$A:$A,0),1),IF($E7="VAM",INDEX(C_Type_Volume!$C:$C,MATCH($D7,C_Type_Volume!$A:$A,0),1),"X")),"") -> 66806 | BB7: =IFERROR(IF($E7="REC",INDEX(A_Type_Volume!$D:$D,MATCH($D7,A_Type_Volume!$A:$A,0),1),IF($E7="VAM",INDEX(C_Type_Volume!$D:$D,MATCH($D7,C_Type_Volume!$A:$A,0),1),"X")),"") -> 66911 | BC7: =IFERROR(IF($E7="REC",INDEX(A_Type_Volume!$E:$E,MATCH($D7,A_Type_Volume!$A:$A,0),1),IF($E7="VAM",INDEX(C_Type_Volume!$E:$E,MATCH($D7,C_Type_Volume!$A:$A,0),1),"X")),"") -> 0 | BD7: =IFERROR(IF($E7="REC",INDEX(A_Type_Volume!$F:$F,MATCH($D7,A_Type_Volume!$A:$A,0),1),IF($E7="VAM",INDEX(C_Type_Volume!$F:$F,MATCH($D7,C_Type_Volume!$A:$A,0),1),"X")),"") -> 0 | BE7: =IFERROR(IF($E7="REC",INDEX(A_Type_Volume!$G:$G,MATCH($D7,A_Type_Volume!$A:$A,0),1),IF($E7="VAM",INDEX(C_Type_Volume!$G:$G,MATCH($D7,C_Type_Volume!$A:$A,0),1),"X")),"") -> 0 | BF7: =IFERROR(IF($E7="REC",INDEX(A_Type_Volume!$H:$H,MATCH($D7,A_Type_Volume!$A:$A,0),1),IF($E7="VAM",INDEX(C_Type_Volume!$H:$H,MATCH($D7,C_Type_Volume!$A:$A,0),1),"X")),"") -> 0 | BG7: =IFERROR(IF($E7="REC",INDEX(A_Type_Volume!$I:$I,MATCH($D7,A_Type_Volume!$A:$A,0),1),IF($E7="VAM",INDEX(C_Type_Volume!$I:$I,MATCH($D7,C_Type_Volume!$A:$A,0),1),"X")),"") -> 0 | BH7: =IFERROR(IF($E7="REC",INDEX(A_Type_Volume!$J:$J,MATCH($D7,A_Type_Volume!$A:$A,0),1),IF($E7="VAM",INDEX(C_Type_Volume!$J:$J,MATCH($D7,C_Type_Volume!$A:$A,0),1),"X")),"") -> 0 | BI7: =IFERROR(IF($E7="REC",INDEX(A_Type_Volume!$K:$K,MATCH($D7,A_Type_Volume!$A:$A,0),1),IF($E7="VAM",INDEX(C_Type_Volume!$K:$K,MATCH($D7,C_Type_Volume!$A:$A,0),1),"X")),"") -> 0 | BJ7: =IFERROR(IF($E7="REC",INDEX(A_Type_Volume!$L:$L,MATCH($D7,A_Type_Volume!$A:$A,0),1),IF($E7="VAM",INDEX(C_Type_Volume!$L:$L,MATCH($D7,C_Type_Volume!$A:$A,0),1),"X")),"") -> 0 | BK7: =IFERROR(IF($E7="REC",INDEX(A_Type_Volume!M:M,MATCH($D7,A_Type_Volume!$A:$A,0),1),IF($E7="VAM",INDEX(C_Type_Volume!M:M,MATCH($D7,C_Type_Volume!$A:$A,0),1),"X")),"") -> 0 | BL7: =SUM(Table1[[#This Row],[Jan_AVF]:[Dec_AVF]]) -> 283542 | BM7: =AZ7*$O7 -> 12439.487 | BN7: =BA7*$O7 -> 5546.6868 | BO7: =BB7*$O7 -> 5555.4046 | BP7: =BC7*$O7 -> 0 | BQ7: =BD7*$O7 -> 0 | BR7: =BE7*$O7 -> 0 | BS7: =BF7*$O7 -> 0 | BT7: =BG7*$O7 -> 0 | ... BX7: =BK7*$O7 -> 0 | BY7: =IFERROR(SUM(BM7:BO7),"") -> 23541.578 | BZ7: =IFERROR(SUM(BP7:BR7),"") -> 0 | CA7: =IFERROR(SUM(BS7:BU7),"") -> 0 | CB7: =IFERROR(SUM(BV7:BX7),"") -> 0 | CC7: =IFERROR(Table1[[#This Row],[Labor Saving]]*Table1[[#This Row],[Annual Volume]],"") -> 0 | CD7: =IFERROR(Table1[[#This Row],[Annual Volume]]*Table1[[#This Row],[Yield Saving]],"") -> 0 | CE7: =IFERROR(Table1[[#This Row],[Annual Volume]]*Table1[[#This Row],[Material Saving]],"") -> 23541.578 | CF7: =IFERROR(Table1[[#This Row],[OH Saving]]*Table1[[#This Row],[Annual Volume]],"") -> 0 | CG7: =SUM(Table1[[#This Row],[Labor_ASV]:[OH_ASV]]) -> 23541.578
A8: =Table1[[#This Row],[Project Name]]&Table1[[#This Row],[Part Number]] -> Aut Visual 2V2 | B8: =IFERROR(Table1[[#This Row],[Project Number]]&Table1[[#This Row],[Part Number]],"") -> AME25-066V2 | C8: AME25-066 | D8: V2 | E8: VAM | F8: =INDEX(Proj_Reg!G:G,MATCH($C8,Proj_Reg!$B:$B,0),1) -> 46174 | G8: =INDEX(Proj_Reg!H:H,MATCH($C8,Proj_Reg!$B:$B,0),1) -> 46508 | H8: =IF(INDEX(Proj_Reg!C:C,MATCH($C8,Proj_Reg!$B:$B,0),1)=0,"",INDEX(Proj_Reg!C:C,MATCH($C8,Proj_Reg!$B:$B,0),1)) -> Visual Inspection | I8: =IF(INDEX(Proj_Reg!D:D,MATCH($C8,Proj_Reg!$B:$B,0),1)=0,"",INDEX(Proj_Reg!D:D,MATCH($C8,Proj_Reg!$B:$B,0),1)) -> XCI | J8: =INDEX(Proj_Reg!E:E,MATCH($C8,Proj_Reg!$B:$B,0),1) -> Aut Visual 2 | K8: 0 | L8: 0 | M8: 0.083026776 | N8: 0 | O8: =SUM(Table1[[#This Row],[Labor Saving]:[OH Saving]]) -> 0.083026776 | Q8: =IFERROR(IF($F8=Q$1,0.3,IF(AND(Q$1>$F8,Q$1<=$G8),100%,0))*AZ8,"") -> 0 | R8: =IFERROR(IF($F8=R$1,0.3,IF(AND(R$1>$F8,R$1<=$G8),100%,0))*BA8,"") -> 0 | S8: =IFERROR(IF($F8=S$1,0.3,IF(AND(S$1>$F8,S$1<=$G8),100%,0))*BB8,"") -> 0 | T8: =IFERROR(IF($F8=T$1,0.3,IF(AND(T$1>$F8,T$1<=$G8),100%,0))*BC8,"") -> 0 | U8: =IFERROR(IF($F8=U$1,0.3,IF(AND(U$1>$F8,U$1<=$G8),100%,0))*BD8,"") -> 0 | V8: =IFERROR(IF($F8=V$1,0.3,IF(AND(V$1>$F8,V$1<=$G8),100%,0))*BE8,"") -> 0 | W8: =IFERROR(IF($F8=W$1,0.3,IF(AND(W$1>$F8,W$1<=$G8),100%,0))*BF8,"") -> 0 | X8: =IFERROR(IF($F8=X$1,0.3,IF(AND(X$1>$F8,X$1<=$G8),100%,0))*BG8,"") -> 0 | Y8: =IFERROR(IF($F8=Y$1,0.7,IF(AND(Y$1>$F8,Y$1<=$G8),100%,0))*BH8,"") -> 0 | Z8: =IFERROR(IF($F8=Z$1,0.3,IF(AND(Z$1>$F8,Z$1<=$G8),100%,0))*BI8,"") -> 0 | AA8: =IFERROR(IF($F8=AA$1,0.3,IF(AND(AA$1>$F8,AA$1<=$G8),100%,0))*BJ8,"") -> 0 | AB8: =IFERROR(IF($F8=AB$1,0.3,IF(AND(AB$1>$F8,AB$1<=$G8),100%,0))*BK8,"") -> 0 | AC8: =SUM(Table1[[#This Row],[Jan]:[Dec]]) -> 0 | AD8: =IFERROR($O8*Q8,"") -> 0 | AE8: =IFERROR($O8*R8,"") -> 0 | AF8: =IFERROR($O8*S8,"") -> 0 | AG8: =IFERROR($O8*T8,"") -> 0 | AH8: =IFERROR($O8*U8,"") -> 0 | AI8: =IFERROR($O8*V8,"") -> 0 | AJ8: =IFERROR($O8*W8,"") -> 0 | AK8: =IFERROR($O8*X8,"") -> 0 | ... AO8: =IFERROR($O8*AB8,"") -> 0 | AP8: =SUM(AD8:AF8) -> 0 | AQ8: =SUM(AG8:AI8) -> 0 | AR8: =SUM(AJ8:AL8) -> 0 | AS8: =SUM(AM8:AO8) -> 0 | AT8: =SUM(AD8:AO8)=SUM(AP8:AS8) -> TRUE | AU8: =IFERROR(K8*SUM($Q8:$AB8),"") -> 0 | AV8: =IFERROR(L8*SUM($Q8:$AB8),"") -> 0 | AW8: =IFERROR(M8*SUM($Q8:$AB8),"") -> 0 | AX8: =IFERROR(N8*SUM($Q8:$AB8),"") -> 0 | AY8: =SUM(AU8:AX8) -> 0 | AZ8: =IFERROR(IF($E8="REC",INDEX(A_Type_Volume!$B:$B,MATCH($D8,A_Type_Volume!$A:$A,0),1),IF($E8="VAM",INDEX(C_Type_Volume!$B:$B,MATCH($D8,C_Type_Volume!$A:$A,0),1),"X")),"") -> 149825 | BA8: =IFERROR(IF($E8="REC",INDEX(A_Type_Volume!$C:$C,MATCH($D8,A_Type_Volume!$A:$A,0),1),IF($E8="VAM",INDEX(C_Type_Volume!$C:$C,MATCH($D8,C_Type_Volume!$A:$A,0),1),"X")),"") -> 66806 | BB8: =IFERROR(IF($E8="REC",INDEX(A_Type_Volume!$D:$D,MATCH($D8,A_Type_Volume!$A:$A,0),1),IF($E8="VAM",INDEX(C_Type_Volume!$D:$D,MATCH($D8,C_Type_Volume!$A:$A,0),1),"X")),"") -> 66911 | BC8: =IFERROR(IF($E8="REC",INDEX(A_Type_Volume!$E:$E,MATCH($D8,A_Type_Volume!$A:$A,0),1),IF($E8="VAM",INDEX(C_Type_Volume!$E:$E,MATCH($D8,C_Type_Volume!$A:$A,0),1),"X")),"") -> 0 | BD8: =IFERROR(IF($E8="REC",INDEX(A_Type_Volume!$F:$F,MATCH($D8,A_Type_Volume!$A:$A,0),1),IF($E8="VAM",INDEX(C_Type_Volume!$F:$F,MATCH($D8,C_Type_Volume!$A:$A,0),1),"X")),"") -> 0 | BE8: =IFERROR(IF($E8="REC",INDEX(A_Type_Volume!$G:$G,MATCH($D8,A_Type_Volume!$A:$A,0),1),IF($E8="VAM",INDEX(C_Type_Volume!$G:$G,MATCH($D8,C_Type_Volume!$A:$A,0),1),"X")),"") -> 0 | BF8: =IFERROR(IF($E8="REC",INDEX(A_Type_Volume!$H:$H,MATCH($D8,A_Type_Volume!$A:$A,0),1),IF($E8="VAM",INDEX(C_Type_Volume!$H:$H,MATCH($D8,C_Type_Volume!$A:$A,0),1),"X")),"") -> 0 | BG8: =IFERROR(IF($E8="REC",INDEX(A_Type_Volume!$I:$I,MATCH($D8,A_Type_Volume!$A:$A,0),1),IF($E8="VAM",INDEX(C_Type_Volume!$I:$I,MATCH($D8,C_Type_Volume!$A:$A,0),1),"X")),"") -> 0 | BH8: =IFERROR(IF($E8="REC",INDEX(A_Type_Volume!$J:$J,MATCH($D8,A_Type_Volume!$A:$A,0),1),IF($E8="VAM",INDEX(C_Type_Volume!$J:$J,MATCH($D8,C_Type_Volume!$A:$A,0),1),"X")),"") -> 0 | BI8: =IFERROR(IF($E8="REC",INDEX(A_Type_Volume!$K:$K,MATCH($D8,A_Type_Volume!$A:$A,0),1),IF($E8="VAM",INDEX(C_Type_Volume!$K:$K,MATCH($D8,C_Type_Volume!$A:$A,0),1),"X")),"") -> 0 | BJ8: =IFERROR(IF($E8="REC",INDEX(A_Type_Volume!$L:$L,MATCH($D8,A_Type_Volume!$A:$A,0),1),IF($E8="VAM",INDEX(C_Type_Volume!$L:$L,MATCH($D8,C_Type_Volume!$A:$A,0),1),"X")),"") -> 0 | BK8: =IFERROR(IF($E8="REC",INDEX(A_Type_Volume!M:M,MATCH($D8,A_Type_Volume!$A:$A,0),1),IF($E8="VAM",INDEX(C_Type_Volume!M:M,MATCH($D8,C_Type_Volume!$A:$A,0),1),"X")),"") -> 0 | BL8: =SUM(Table1[[#This Row],[Jan_AVF]:[Dec_AVF]]) -> 283542 | BM8: =AZ8*$O8 -> 12439.487 | BN8: =BA8*$O8 -> 5546.6868 | BO8: =BB8*$O8 -> 5555.4046 | BP8: =BC8*$O8 -> 0 | BQ8: =BD8*$O8 -> 0 | BR8: =BE8*$O8 -> 0 | BS8: =BF8*$O8 -> 0 | BT8: =BG8*$O8 -> 0 | ... BX8: =BK8*$O8 -> 0 | BY8: =IFERROR(SUM(BM8:BO8),"") -> 23541.578 | BZ8: =IFERROR(SUM(BP8:BR8),"") -> 0 | CA8: =IFERROR(SUM(BS8:BU8),"") -> 0 | CB8: =IFERROR(SUM(BV8:BX8),"") -> 0 | CC8: =IFERROR(Table1[[#This Row],[Labor Saving]]*Table1[[#This Row],[Annual Volume]],"") -> 0 | CD8: =IFERROR(Table1[[#This Row],[Annual Volume]]*Table1[[#This Row],[Yield Saving]],"") -> 0 | CE8: =IFERROR(Table1[[#This Row],[Annual Volume]]*Table1[[#This Row],[Material Saving]],"") -> 23541.578 | CF8: =IFERROR(Table1[[#This Row],[OH Saving]]*Table1[[#This Row],[Annual Volume]],"") -> 0 | CG8: =SUM(Table1[[#This Row],[Labor_ASV]:[OH_ASV]]) -> 23541.578
A9: =Table1[[#This Row],[Project Name]]&Table1[[#This Row],[Part Number]] -> TiW Target Supplier ZR182 | B9: =IFERROR(Table1[[#This Row],[Project Number]]&Table1[[#This Row],[Part Number]],"") -> AME25-003R182 | C9: AME25-003 | D9: R182 | E9: REC | F9: =INDEX(Proj_Reg!G:G,MATCH($C9,Proj_Reg!$B:$B,0),1) -> 45809 | G9: =INDEX(Proj_Reg!H:H,MATCH($C9,Proj_Reg!$B:$B,0),1) -> 46143 | H9: =IF(INDEX(Proj_Reg!C:C,MATCH($C9,Proj_Reg!$B:$B,0),1)=0,"",INDEX(Proj_Reg!C:C,MATCH($C9,Proj_Reg!$B:$B,0),1)) -> Sputtering | I9: =IF(INDEX(Proj_Reg!D:D,MATCH($C9,Proj_Reg!$B:$B,0),1)=0,"",INDEX(Proj_Reg!D:D,MATCH($C9,Proj_Reg!$B:$B,0),1)) -> XWP | J9: =INDEX(Proj_Reg!E:E,MATCH($C9,Proj_Reg!$B:$B,0),1) -> TiW Target Supplier Z | K9: 0.029517215 | L9: 0 | M9: 0.011653969 | N9: 0 | O9: =SUM(Table1[[#This Row],[Labor Saving]:[OH Saving]]) -> 0.041171184 | Q9: =IFERROR(IF($F9=Q$1,0.3,IF(AND(Q$1>$F9,Q$1<=$G9),100%,0))*AZ9,"") -> 0 | R9: =IFERROR(IF($F9=R$1,0.3,IF(AND(R$1>$F9,R$1<=$G9),100%,0))*BA9,"") -> 0 | S9: =IFERROR(IF($F9=S$1,0.3,IF(AND(S$1>$F9,S$1<=$G9),100%,0))*BB9,"") -> 0 | T9: =IFERROR(IF($F9=T$1,0.3,IF(AND(T$1>$F9,T$1<=$G9),100%,0))*BC9,"") -> 0 | U9: =IFERROR(IF($F9=U$1,0.3,IF(AND(U$1>$F9,U$1<=$G9),100%,0))*BD9,"") -> 0 | V9: =IFERROR(IF($F9=V$1,0.3,IF(AND(V$1>$F9,V$1<=$G9),100%,0))*BE9,"") -> 0 | W9: =IFERROR(IF($F9=W$1,0.3,IF(AND(W$1>$F9,W$1<=$G9),100%,0))*BF9,"") -> 0 | X9: =IFERROR(IF($F9=X$1,0.3,IF(AND(X$1>$F9,X$1<=$G9),100%,0))*BG9,"") -> 0 | Y9: =IFERROR(IF($F9=Y$1,0.7,IF(AND(Y$1>$F9,Y$1<=$G9),100%,0))*BH9,"") -> 0 | Z9: =IFERROR(IF($F9=Z$1,0.3,IF(AND(Z$1>$F9,Z$1<=$G9),100%,0))*BI9,"") -> 0 | AA9: =IFERROR(IF($F9=AA$1,0.3,IF(AND(AA$1>$F9,AA$1<=$G9),100%,0))*BJ9,"") -> 0 | AB9: =IFERROR(IF($F9=AB$1,0.3,IF(AND(AB$1>$F9,AB$1<=$G9),100%,0))*BK9,"") -> 0 | AC9: =SUM(Table1[[#This Row],[Jan]:[Dec]]) -> 0 | AD9: =IFERROR($O9*Q9,"") -> 0 | AE9: =IFERROR($O9*R9,"") -> 0 | AF9: =IFERROR($O9*S9,"") -> 0 | AG9: =IFERROR($O9*T9,"") -> 0 | AH9: =IFERROR($O9*U9,"") -> 0 | AI9: =IFERROR($O9*V9,"") -> 0 | AJ9: =IFERROR($O9*W9,"") -> 0 | AK9: =IFERROR($O9*X9,"") -> 0 | ... AO9: =IFERROR($O9*AB9,"") -> 0 | AP9: =SUM(AD9:AF9) -> 0 | AQ9: =SUM(AG9:AI9) -> 0 | AR9: =SUM(AJ9:AL9) -> 0 | AS9: =SUM(AM9:AO9) -> 0 | AT9: =SUM(AD9:AO9)=SUM(AP9:AS9) -> TRUE | AU9: =IFERROR(K9*SUM($Q9:$AB9),"") -> 0 | AV9: =IFERROR(L9*SUM($Q9:$AB9),"") -> 0 | AW9: =IFERROR(M9*SUM($Q9:$AB9),"") -> 0 | AX9: =IFERROR(N9*SUM($Q9:$AB9),"") -> 0 | AY9: =SUM(AU9:AX9) -> 0 | AZ9: =IFERROR(IF($E9="REC",INDEX(A_Type_Volume!$B:$B,MATCH($D9,A_Type_Volume!$A:$A,0),1),IF($E9="VAM",INDEX(C_Type_Volume!$B:$B,MATCH($D9,C_Type_Volume!$A:$A,0),1),"X")),"") -> 0 | BA9: =IFERROR(IF($E9="REC",INDEX(A_Type_Volume!$C:$C,MATCH($D9,A_Type_Volume!$A:$A,0),1),IF($E9="VAM",INDEX(C_Type_Volume!$C:$C,MATCH($D9,C_Type_Volume!$A:$A,0),1),"X")),"") -> 0 | BB9: =IFERROR(IF($E9="REC",INDEX(A_Type_Volume!$D:$D,MATCH($D9,A_Type_Volume!$A:$A,0),1),IF($E9="VAM",INDEX(C_Type_Volume!$D:$D,MATCH($D9,C_Type_Volume!$A:$A,0),1),"X")),"") -> 0 | BC9: =IFERROR(IF($E9="REC",INDEX(A_Type_Volume!$E:$E,MATCH($D9,A_Type_Volume!$A:$A,0),1),IF($E9="VAM",INDEX(C_Type_Volume!$E:$E,MATCH($D9,C_Type_Volume!$A:$A,0),1),"X")),"") -> 0 | BD9: =IFERROR(IF($E9="REC",INDEX(A_Type_Volume!$F:$F,MATCH($D9,A_Type_Volume!$A:$A,0),1),IF($E9="VAM",INDEX(C_Type_Volume!$F:$F,MATCH($D9,C_Type_Volume!$A:$A,0),1),"X")),"") -> 0 | BE9: =IFERROR(IF($E9="REC",INDEX(A_Type_Volume!$G:$G,MATCH($D9,A_Type_Volume!$A:$A,0),1),IF($E9="VAM",INDEX(C_Type_Volume!$G:$G,MATCH($D9,C_Type_Volume!$A:$A,0),1),"X")),"") -> 0 | BF9: =IFERROR(IF($E9="REC",INDEX(A_Type_Volume!$H:$H,MATCH($D9,A_Type_Volume!$A:$A,0),1),IF($E9="VAM",INDEX(C_Type_Volume!$H:$H,MATCH($D9,C_Type_Volume!$A:$A,0),1),"X")),"") -> 0 | BG9: =IFERROR(IF($E9="REC",INDEX(A_Type_Volume!$I:$I,MATCH($D9,A_Type_Volume!$A:$A,0),1),IF($E9="VAM",INDEX(C_Type_Volume!$I:$I,MATCH($D9,C_Type_Volume!$A:$A,0),1),"X")),"") -> 0 | BH9: =IFERROR(IF($E9="REC",INDEX(A_Type_Volume!$J:$J,MATCH($D9,A_Type_Volume!$A:$A,0),1),IF($E9="VAM",INDEX(C_Type_Volume!$J:$J,MATCH($D9,C_Type_Volume!$A:$A,0),1),"X")),"") -> 0 | BI9: =IFERROR(IF($E9="REC",INDEX(A_Type_Volume!$K:$K,MATCH($D9,A_Type_Volume!$A:$A,0),1),IF($E9="VAM",INDEX(C_Type_Volume!$K:$K,MATCH($D9,C_Type_Volume!$A:$A,0),1),"X")),"") -> 0 | BJ9: =IFERROR(IF($E9="REC",INDEX(A_Type_Volume!$L:$L,MATCH($D9,A_Type_Volume!$A:$A,0),1),IF($E9="VAM",INDEX(C_Type_Volume!$L:$L,MATCH($D9,C_Type_Volume!$A:$A,0),1),"X")),"") -> 0 | BK9: =IFERROR(IF($E9="REC",INDEX(A_Type_Volume!M:M,MATCH($D9,A_Type_Volume!$A:$A,0),1),IF($E9="VAM",INDEX(C_Type_Volume!M:M,MATCH($D9,C_Type_Volume!$A:$A,0),1),"X")),"") -> 0 | BL9: =SUM(Table1[[#This Row],[Jan_AVF]:[Dec_AVF]]) -> 0 | BM9: =AZ9*$O9 -> 0 | BN9: =BA9*$O9 -> 0 | BO9: =BB9*$O9 -> 0 | BP9: =BC9*$O9 -> 0 | BQ9: =BD9*$O9 -> 0 | BR9: =BE9*$O9 -> 0 | BS9: =BF9*$O9 -> 0 | BT9: =BG9*$O9 -> 0 | ... BX9: =BK9*$O9 -> 0 | BY9: =IFERROR(SUM(BM9:BO9),"") -> 0 | BZ9: =IFERROR(SUM(BP9:BR9),"") -> 0 | CA9: =IFERROR(SUM(BS9:BU9),"") -> 0 | CB9: =IFERROR(SUM(BV9:BX9),"") -> 0 | CC9: =IFERROR(Table1[[#This Row],[Labor Saving]]*Table1[[#This Row],[Annual Volume]],"") -> 0 | CD9: =IFERROR(Table1[[#This Row],[Annual Volume]]*Table1[[#This Row],[Yield Saving]],"") -> 0 | CE9: =IFERROR(Table1[[#This Row],[Annual Volume]]*Table1[[#This Row],[Material Saving]],"") -> 0 | CF9: =IFERROR(Table1[[#This Row],[OH Saving]]*Table1[[#This Row],[Annual Volume]],"") -> 0 | CG9: =SUM(Table1[[#This Row],[Labor_ASV]:[OH_ASV]]) -> 0
A10: =Table1[[#This Row],[Project Name]]&Table1[[#This Row],[Part Number]] -> TiW Target Supplier ZR183 | B10: =IFERROR(Table1[[#This Row],[Project Number]]&Table1[[#This Row],[Part Number]],"") -> AME25-003R183 | C10: AME25-003 | D10: R183 | E10: REC | F10: =INDEX(Proj_Reg!G:G,MATCH($C10,Proj_Reg!$B:$B,0),1) -> 45809 | G10: =INDEX(Proj_Reg!H:H,MATCH($C10,Proj_Reg!$B:$B,0),1) -> 46143 | H10: =IF(INDEX(Proj_Reg!C:C,MATCH($C10,Proj_Reg!$B:$B,0),1)=0,"",INDEX(Proj_Reg!C:C,MATCH($C10,Proj_Reg!$B:$B,0),1)) -> Sputtering | I10: =IF(INDEX(Proj_Reg!D:D,MATCH($C10,Proj_Reg!$B:$B,0),1)=0,"",INDEX(Proj_Reg!D:D,MATCH($C10,Proj_Reg!$B:$B,0),1)) -> XWP | J10: =INDEX(Proj_Reg!E:E,MATCH($C10,Proj_Reg!$B:$B,0),1) -> TiW Target Supplier Z | K10: 0.029517215 | L10: 0 | M10: 0.011653969 | N10: 0 | O10: =SUM(Table1[[#This Row],[Labor Saving]:[OH Saving]]) -> 0.041171184 | Q10: =IFERROR(IF($F10=Q$1,0.3,IF(AND(Q$1>$F10,Q$1<=$G10),100%,0))*AZ10,"") -> 0 | R10: =IFERROR(IF($F10=R$1,0.3,IF(AND(R$1>$F10,R$1<=$G10),100%,0))*BA10,"") -> 0 | S10: =IFERROR(IF($F10=S$1,0.3,IF(AND(S$1>$F10,S$1<=$G10),100%,0))*BB10,"") -> 0 | T10: =IFERROR(IF($F10=T$1,0.3,IF(AND(T$1>$F10,T$1<=$G10),100%,0))*BC10,"") -> 0 | U10: =IFERROR(IF($F10=U$1,0.3,IF(AND(U$1>$F10,U$1<=$G10),100%,0))*BD10,"") -> 0 | V10: =IFERROR(IF($F10=V$1,0.3,IF(AND(V$1>$F10,V$1<=$G10),100%,0))*BE10,"") -> 0 | W10: =IFERROR(IF($F10=W$1,0.3,IF(AND(W$1>$F10,W$1<=$G10),100%,0))*BF10,"") -> 0 | X10: =IFERROR(IF($F10=X$1,0.3,IF(AND(X$1>$F10,X$1<=$G10),100%,0))*BG10,"") -> 0 | Y10: =IFERROR(IF($F10=Y$1,0.7,IF(AND(Y$1>$F10,Y$1<=$G10),100%,0))*BH10,"") -> 0 | Z10: =IFERROR(IF($F10=Z$1,0.3,IF(AND(Z$1>$F10,Z$1<=$G10),100%,0))*BI10,"") -> 0 | AA10: =IFERROR(IF($F10=AA$1,0.3,IF(AND(AA$1>$F10,AA$1<=$G10),100%,0))*BJ10,"") -> 0 | AB10: =IFERROR(IF($F10=AB$1,0.3,IF(AND(AB$1>$F10,AB$1<=$G10),100%,0))*BK10,"") -> 0 | AC10: =SUM(Table1[[#This Row],[Jan]:[Dec]]) -> 0 | AD10: =IFERROR($O10*Q10,"") -> 0 | AE10: =IFERROR($O10*R10,"") -> 0 | AF10: =IFERROR($O10*S10,"") -> 0 | AG10: =IFERROR($O10*T10,"") -> 0 | AH10: =IFERROR($O10*U10,"") -> 0 | AI10: =IFERROR($O10*V10,"") -> 0 | AJ10: =IFERROR($O10*W10,"") -> 0 | AK10: =IFERROR($O10*X10,"") -> 0 | ... AO10: =IFERROR($O10*AB10,"") -> 0 | AP10: =SUM(AD10:AF10) -> 0 | AQ10: =SUM(AG10:AI10) -> 0 | AR10: =SUM(AJ10:AL10) -> 0 | AS10: =SUM(AM10:AO10) -> 0 | AT10: =SUM(AD10:AO10)=SUM(AP10:AS10) -> TRUE | AU10: =IFERROR(K10*SUM($Q10:$AB10),"") -> 0 | AV10: =IFERROR(L10*SUM($Q10:$AB10),"") -> 0 | AW10: =IFERROR(M10*SUM($Q10:$AB10),"") -> 0 | AX10: =IFERROR(N10*SUM($Q10:$AB10),"") -> 0 | AY10: =SUM(AU10:AX10) -> 0 | AZ10: =IFERROR(IF($E10="REC",INDEX(A_Type_Volume!$B:$B,MATCH($D10,A_Type_Volume!$A:$A,0),1),IF($E10="VAM",INDEX(C_Type_Volume!$B:$B,MATCH($D10,C_Type_Volume!$A:$A,0),1),"X")),"") -> 0 | BA10: =IFERROR(IF($E10="REC",INDEX(A_Type_Volume!$C:$C,MATCH($D10,A_Type_Volume!$A:$A,0),1),IF($E10="VAM",INDEX(C_Type_Volume!$C:$C,MATCH($D10,C_Type_Volume!$A:$A,0),1),"X")),"") -> 0 | BB10: =IFERROR(IF($E10="REC",INDEX(A_Type_Volume!$D:$D,MATCH($D10,A_Type_Volume!$A:$A,0),1),IF($E10="VAM",INDEX(C_Type_Volume!$D:$D,MATCH($D10,C_Type_Volume!$A:$A,0),1),"X")),"") -> 0 | BC10: =IFERROR(IF($E10="REC",INDEX(A_Type_Volume!$E:$E,MATCH($D10,A_Type_Volume!$A:$A,0),1),IF($E10="VAM",INDEX(C_Type_Volume!$E:$E,MATCH($D10,C_Type_Volume!$A:$A,0),1),"X")),"") -> 0 | BD10: =IFERROR(IF($E10="REC",INDEX(A_Type_Volume!$F:$F,MATCH($D10,A_Type_Volume!$A:$A,0),1),IF($E10="VAM",INDEX(C_Type_Volume!$F:$F,MATCH($D10,C_Type_Volume!$A:$A,0),1),"X")),"") -> 0 | BE10: =IFERROR(IF($E10="REC",INDEX(A_Type_Volume!$G:$G,MATCH($D10,A_Type_Volume!$A:$A,0),1),IF($E10="VAM",INDEX(C_Type_Volume!$G:$G,MATCH($D10,C_Type_Volume!$A:$A,0),1),"X")),"") -> 0 | BF10: =IFERROR(IF($E10="REC",INDEX(A_Type_Volume!$H:$H,MATCH($D10,A_Type_Volume!$A:$A,0),1),IF($E10="VAM",INDEX(C_Type_Volume!$H:$H,MATCH($D10,C_Type_Volume!$A:$A,0),1),"X")),"") -> 0 | BG10: =IFERROR(IF($E10="REC",INDEX(A_Type_Volume!$I:$I,MATCH($D10,A_Type_Volume!$A:$A,0),1),IF($E10="VAM",INDEX(C_Type_Volume!$I:$I,MATCH($D10,C_Type_Volume!$A:$A,0),1),"X")),"") -> 0 | BH10: =IFERROR(IF($E10="REC",INDEX(A_Type_Volume!$J:$J,MATCH($D10,A_Type_Volume!$A:$A,0),1),IF($E10="VAM",INDEX(C_Type_Volume!$J:$J,MATCH($D10,C_Type_Volume!$A:$A,0),1),"X")),"") -> 0 | BI10: =IFERROR(IF($E10="REC",INDEX(A_Type_Volume!$K:$K,MATCH($D10,A_Type_Volume!$A:$A,0),1),IF($E10="VAM",INDEX(C_Type_Volume!$K:$K,MATCH($D10,C_Type_Volume!$A:$A,0),1),"X")),"") -> 0 | BJ10: =IFERROR(IF($E10="REC",INDEX(A_Type_Volume!$L:$L,MATCH($D10,A_Type_Volume!$A:$A,0),1),IF($E10="VAM",INDEX(C_Type_Volume!$L:$L,MATCH($D10,C_Type_Volume!$A:$A,0),1),"X")),"") -> 0 | BK10: =IFERROR(IF($E10="REC",INDEX(A_Type_Volume!M:M,MATCH($D10,A_Type_Volume!$A:$A,0),1),IF($E10="VAM",INDEX(C_Type_Volume!M:M,MATCH($D10,C_Type_Volume!$A:$A,0),1),"X")),"") -> 0 | BL10: =SUM(Table1[[#This Row],[Jan_AVF]:[Dec_AVF]]) -> 0 | BM10: =AZ10*$O10 -> 0 | BN10: =BA10*$O10 -> 0 | BO10: =BB10*$O10 -> 0 | BP10: =BC10*$O10 -> 0 | BQ10: =BD10*$O10 -> 0 | BR10: =BE10*$O10 -> 0 | BS10: =BF10*$O10 -> 0 | BT10: =BG10*$O10 -> 0 | ... BX10: =BK10*$O10 -> 0 | BY10: =IFERROR(SUM(BM10:BO10),"") -> 0 | BZ10: =IFERROR(SUM(BP10:BR10),"") -> 0 | CA10: =IFERROR(SUM(BS10:BU10),"") -> 0 | CB10: =IFERROR(SUM(BV10:BX10),"") -> 0 | CC10: =IFERROR(Table1[[#This Row],[Labor Saving]]*Table1[[#This Row],[Annual Volume]],"") -> 0 | CD10: =IFERROR(Table1[[#This Row],[Annual Volume]]*Table1[[#This Row],[Yield Saving]],"") -> 0 | CE10: =IFERROR(Table1[[#This Row],[Annual Volume]]*Table1[[#This Row],[Material Saving]],"") -> 0 | CF10: =IFERROR(Table1[[#This Row],[OH Saving]]*Table1[[#This Row],[Annual Volume]],"") -> 0 | CG10: =SUM(Table1[[#This Row],[Labor_ASV]:[OH_ASV]]) -> 0
